<?xml version="1.0"?>
<robot xmlns:xacro="http://www.ros.org/wiki/xacro" name="rover">

    <xacro:include filename="inertial_macros.xacro"/>

    <material name="white">
        <color rgba="1 1 1 1"/>
    </material>   

    <material name="orange">
        <color rgba="1 0.3 0.1 1"/>
    </material> 

    <material name="blue">
        <color rgba="0.2 0.2 1 1"/>
    </material>

    <material name="black">
        <color rgba="0 0 0 1"/>
    </material>

    <material name="red">
        <color rgba="1 0 0 1"/>
    </material>

    <!-- BASE  -->
    <link name="base_link"></link>

    <joint name="base_link_joint" type="fixed">
        <origin xyz="0.0 0.0 0.1" rpy="0.0 0.0 0.0"/>
        <parent link="base_link"/>
        <child link="chassis_link"/>
        <axis xyz="0.0 0.0 0.0"/>
    </joint>

    <joint name="base_footprint_joint" type="fixed">
        <origin xyz="0.0 0.0 0.1" rpy="0.0 0.0 0.0"/>
        <parent link="base_link"/>
        <child link="base_footprint"/>
        <axis xyz="0.0 0.0 0.0"/>
    </joint>

    <link name="base_footprint"></link>
    
    <!-- CHASSIS -->
    <link name="chassis_link">
        <visual>
            <origin xyz="0.0 0.0 0.0"/>
            <geometry>
                <box size="0.8 0.7 0.3"/>
            </geometry>
            <material name="orange"/>
        </visual>

        <collision>
            <geometry>
                <box size="0.8 0.7 0.3"/>
            </geometry>
        </collision>
        <xacro:inertial_box mass="0.5" x="0.8" y="0.7" z="0.3">
            <origin xyz="0.0 0.0 0.0" rpy="0 0 0"/>
        </xacro:inertial_box>
    </link>

    <gazebo reference="chassis_link">
        <material>Gazebo/Orange</material>
    </gazebo>

    <joint name="wheel_front_right_joint" type="continuous">
        <origin xyz="-0.15 0.4 0.0" rpy="1.57 0.0 0.0"/>
        <parent link="base_link"/>
        <child link="wheel_front_right_link"/>
        <axis xyz="0.0 0.0 1.0"/>
    </joint>

    <!-- WHEEL FRONT RIGHT  -->
    <link name="wheel_front_right_link">
        <visual>
            <geometry>
                <cylinder radius="0.15" length="0.1"/>
            </geometry>
            <material name="white"/>
        </visual>

        <collision>
            <geometry>
                <cylinder radius="0.15" length="0.1"/>
            </geometry>
        </collision>
        <xacro:inertial_cylinder mass="0.1" length="0.15" radius="0.15">
            <origin xyz="0 0 0" rpy="0 0 0"/>
        </xacro:inertial_cylinder>
    </link>

    <gazebo reference="wheel_front_right_link">
        <material>Gazebo/White</material>
    </gazebo>

    <joint name="wheel_front_left_joint_joint" type="continuous">
        <origin xyz="-0.15 -0.4 0.0" rpy="1.57 0.0 0.0"/>
        <parent link="base_link"/>
        <child link="wheel_front_left_link"/>
        <axis xyz="0.0 0.0 1.0"/>
    </joint>

    <!-- WHEEL FRONT LEFT  -->
    <link name="wheel_front_left_link">
        <visual>
            <geometry>
                <cylinder radius="0.15" length="0.1"/>
            </geometry>
            <material name="white"/>
        </visual>

        <collision>
            <geometry>
                <cylinder radius="0.15" length="0.15"/>
            </geometry>
        </collision>

        <xacro:inertial_cylinder mass="0.1" length="0.15" radius="0.15">
            <origin xyz="0 0 0" rpy="0 0 0"/>
        </xacro:inertial_cylinder>
    </link>

    <gazebo reference="wheel_front_left_link">
        <material>Gazebo/White</material>
    </gazebo>


    <!-- CASTER HOLDER -->
    <joint name="caster_cylinder_joint_joint" type="fixed">
        <origin xyz="0.3 0.0 -0.1"/>
        <parent link="chassis_link"/>
        <child link="caster_cylinder_link"/>
    </joint>

    <link name="caster_cylinder_link">
        <visual>
            <geometry>
                <cylinder radius="0.05" length="0.2"/>
            </geometry>
            <material name="black"/>
        </visual>

        <collision>
            <geometry>
                <cylinder radius="0.05" length="0.2"/>
            </geometry>
        </collision>
        <xacro:inertial_cylinder mass="0.1" length="0.2" radius="0.05">
            <origin xyz="0 0 0" rpy="0 0 0"/>
        </xacro:inertial_cylinder>
    </link>
    
    <gazebo reference="caster_cylinder_link">
        <material>Gazebo/Black</material>
    </gazebo>

    <joint name="caster_joint_joint" type="fixed">
        <origin xyz="0.0 0.0 -0.1"/>
        <parent link="caster_cylinder_link"/>
        <child link="caster_wheel_link"/>
    </joint>

    <!-- CASTER WHEEL -->
    <link name="caster_wheel_link">
        <visual>
            <geometry>
                <sphere  radius="0.05"/>
            </geometry>
        </visual>

        <collision>
            <geometry>
                <sphere  radius="0.05"/>
            </geometry>
        </collision>

        <xacro:inertial_sphere mass="0.1" radius="0.05">
            <origin xyz="0 0 0" rpy="0 0 0"/>
        </xacro:inertial_sphere>
    </link>

    <gazebo reference="caster_wheel_link">
        <material>Gazebo/Black</material>
        <mu1 value="0.001"/>
        <mu2 value="0.001"/>
    </gazebo>

    <joint name="lidar_joint" type="fixed">
        <origin xyz="0.0 0.0 0.25" rpy="0 0 1.5708"/> 
        <parent link="chassis_link"/>
        <child link="lidar_holder"/>
    </joint>

    <!-- LIDAR -->
    <link name="lidar_holder">
        <visual>
            <geometry>
                <cylinder radius="0.05" length="0.25"/>
            </geometry>
            <material name="red"/>
        </visual>

        <collision>
            <geometry>
                <cylinder radius="0.05" length="0.25"/>
            </geometry>
        </collision>
        <xacro:inertial_cylinder mass="0.1" length="0.25" radius="0.05">
            <origin xyz="0 0 0" rpy="0 0 0"/>
        </xacro:inertial_cylinder>
    </link>

    <gazebo reference="lidar_holder">
        <material>Gazebo/Red</material>
    </gazebo>

     <!-- LIDAR HOLDER -->
     <joint name="lidar_holder_joint" type="fixed">
        <origin xyz="0.0 0.0 0.15" rpy="0.0 0.0 0"/>
        <parent link="lidar_holder"/>
        <child link="lidar_link"/>
    </joint>

     <!-- LIDAR -->
     <link name="lidar_link">
        <visual>
            <geometry>
                <cylinder radius="0.1" length="0.05"/>
            </geometry>
            <material name="blue"/>
        </visual>

        <collision>
            <geometry>
                <cylinder radius="0.1" length="0.05"/>
            </geometry>
        </collision>
        <xacro:inertial_cylinder mass="0.1" length="0.2" radius="0.1">
            <origin xyz="0 0 0" rpy="0 0 0"/>
        </xacro:inertial_cylinder>
    </link>

    <!-- CAMERA -->
    <joint name="camera_joint" type="fixed">
        <origin xyz="-0.38 0.0 0.25" rpy="0 0 ${pi}"/>
        <parent link="chassis_link"/>
        <child link="camera_link"/>
    </joint>

    <link name="camera_link">
        <visual>
            <geometry>
                <box size="0.04 0.1 0.2"/> 
            </geometry>
            <material name="black"/>
        </visual>

        <collision>
            <geometry>
                <box size="0.05 0.1 0.2"/> 
            </geometry>
        </collision>
    </link>

    <joint name="camera_optical_joint" type="fixed">
        <parent link="camera_link"/>
        <child link="camera_link_optical"/>
        <origin xyz="0 0 0" rpy="${-pi/2} 0 ${-pi/2}"/>
    </joint>

    <link name="camera_link_optical"></link>

    <!-- GAZEBO Lidar Plugin -->
    <gazebo reference="lidar_link">
        <material>Gazebo/Blue</material>
        <sensor name="laser" type="ray">
          <pose> 0 0 0 0 0 0 </pose>
          <visualize>true</visualize>
          <update_rate>10</update_rate>
          <ray>
            <scan>
              <horizontal>
                <samples>360</samples>
                <!-- <resolution>1</resolution> -->
                <!-- <min_angle>0.00</min_angle> -->
                <min_angle>0.00</min_angle>
                <max_angle>3.14</max_angle>
              </horizontal>
            </scan>
            <range>
              <min>0.3</min>
              <max>12</max>
              <!-- <min>0.120</min>
              <max>3.5</max> -->
              <!-- <resolution>0.015</resolution> -->
            </range>
          </ray>
          <plugin name="laser_controller" filename="libgazebo_ros_ray_sensor.so">
            <ros>
                <remapping>~/out:=scan</remapping>
            </ros>
          <output_type>sensor_msgs/LaserScan</output_type>
          <frame_name>lidar_link</frame_name>
          </plugin>
        </sensor>
      </gazebo>

    <!-- CAMERA  Plugin -->
    <gazebo reference="camera_link">
        <material>Gazebo/Black</material>
        <sensor type="camera" name="camera">
        <pose>0 0 0 0 0 0</pose>
        <visualize>true</visualize>
        <update_rate>10.0</update_rate>
        <camera name="head">
        <horizontal_fov>1.3962634</horizontal_fov>
        <image>
            <width>800</width>
            <height>800</height>
            <format>R8G8B8</format>
        </image>
        <clip>
            <near>0.02</near>
            <far>300</far>
        </clip>
        </camera>
        <plugin name="camera_controller" filename="libgazebo_ros_camera.so">
            <alwaysOn>true</alwaysOn>
            <updateRate>0.0</updateRate>
            <cameraName>rrbot/camera1</cameraName>
            <imageTopicName>image_raw</imageTopicName>
            <cameraInfoTopicName>camera_info</cameraInfoTopicName>
            <frameName>camera_link</frameName>
            <hackBaseline>0.07</hackBaseline>
            <distortionK1>0.0</distortionK1>
            <distortionK2>0.0</distortionK2>
            <distortionK3>0.0</distortionK3>
            <distortionT1>0.0</distortionT1>
            <distortionT2>0.0</distortionT2>
        </plugin>
        </sensor>
    </gazebo>
</robot>